<?xml version="1.0"?>
<robot xmlns:xacro="http://www.ros.org/wiki/xacro" name="barista_robot">

    <xacro:property name="include_laser" default="true" />

    <xacro:include filename="$(find barista_robot_description)/xacro/wheel.xacro" />
    <xacro:include filename="$(find barista_robot_description)/xacro/standoff.xacro" />
    <xacro:include filename="$(find barista_robot_description)/xacro/cup_holder_tray.xacro" />

    <material name="red">
        <color rgba="1.0 0.0 0.0 1"/>
    </material>

    <material name="green_light">
        <color rgba="0.0 1.0 0.0 1"/>
    </material>

    <material name="green_dark">
        <color rgba="0.0 0.5 0.0 1"/>
    </material>

    <material name="blue">
        <color rgba="0.0 0.0 1.0 1"/>
    </material>

    <material name="yellow">
        <color rgba="1.0 1.0 0.0 1"/>
    </material>

    <!-- ******************************************** Links ******************************************** -->
    <link name="base_link">
        <visual>        
            <origin rpy="0 0 0" xyz="0 0 0" />
            <geometry>
                <cylinder length="0.155" radius="0.178"/>
            </geometry>
            <material name="red"/>
        </visual>

        <collision>
            <geometry>
                <cylinder length="0.155" radius="0.178"/>
            </geometry>
        </collision>

        <inertial>
            <mass value="1.0"/>
            <origin rpy="0 0 0" xyz="0 0 0"/>
            <inertia ixx="0.009923083333333332" ixy="0" ixz="0" iyy="0.009923083333333332" iyz="0" izz="0.015842"/>
        </inertial>

    </link>

    <gazebo reference="base_link">
        <material>Gazebo/Red</material>
    </gazebo>

    <xacro:standoff standoff_name="standoff_rods_1"/>

    <xacro:standoff standoff_name="standoff_rods_2"/>

    <xacro:standoff standoff_name="standoff_rods_3"/>

    <xacro:standoff standoff_name="standoff_rods_4"/>

    <xacro:cup_holder_tray cup_holder_tray_name="cup_holder_tray"/>

    <gazebo reference="cup_holder_tray">
        <material>Gazebo/Red</material>
    </gazebo>

    <!-- Wheel Left -->
    <xacro:wheel wheel_name="left_wheel" />

    <!-- Wheel Right -->
    <xacro:wheel wheel_name="right_wheel" />

    <gazebo reference="left_wheel">
        <kp>1000000000000000000000000000.0</kp>
        <kd>1000000000000000000000000000.0</kd>
        <mu1>10.0</mu1>
        <mu2>10.0</mu2>
        <material>Gazebo/Black</material>
    </gazebo>

    <gazebo reference="right_wheel">
        <kp>1000000000000000000000000000.0</kp>
        <kd>1000000000000000000000000000.0</kd>
        <mu1>10.0</mu1>
        <mu2>10.0</mu2>
        <material>Gazebo/Black</material>
    </gazebo>

    <!-- Caster Wheel Front -->
    <link name="front_yaw_link">
        <visual>
            <origin rpy="0 1.5707 1.5707" xyz="0 0 0"/>
            <geometry>          
                <cylinder length="0.001" radius="0.0352"/>
            </geometry>
            <material name="blue"/>
        </visual>

        <collision>
            <origin rpy="0 1.5707 1.5707" xyz="0 0 0"/>
            <geometry>
                <cylinder length="0.001" radius="0.0352"/>
            </geometry>
        </collision>

        <inertial>
            <origin rpy="0 1.5707 1.5707" xyz="0 0 0"/>
            <mass value="0.001"/>
            <inertia ixx="3.0984333333333335e-07" ixy="0" ixz="0" iyy="3.0984333333333335e-07" iyz="0" izz="6.195200000000001e-07"/>
        </inertial>

    </link>

    <gazebo reference="front_yaw_link">
        <material>Gazebo/Blue</material>
    </gazebo>

    <link name="front_roll_link">
        <visual>
        <origin rpy="0 1.5707 1.5707" xyz="0 0 0"/>
        <geometry>
            <cylinder length="0.001" radius="0.0352"/>
        </geometry>
        <material name="red"/>
        </visual>

        <collision>
        <origin rpy="0 1.5707 1.5707" xyz="0 0 0"/>
        <geometry>
            <cylinder length="0.001" radius="0.0352"/>
        </geometry>
        </collision>

        <inertial>
            <origin rpy="0 1.5707 1.5707" xyz="0 0 0"/>
            <mass value="0.001"/>
            <inertia ixx="3.0984333333333335e-07" ixy="0" ixz="0" iyy="3.0984333333333335e-07" iyz="0" izz="6.195200000000001e-07"/>
        </inertial>
    </link>

    <gazebo reference="front_roll_link">
        <material>Gazebo/Red</material>
    </gazebo>

    <link name="front_pitch_link">
        <visual>
            <origin rpy="0 1.5707 1.5707" xyz="0 0 0"/>
            <geometry>
                <sphere radius="0.0352"/>
            </geometry>
            <material name="yellow"/>
        </visual>

        <collision>
            <origin rpy="0 1.5707 1.5707" xyz="0 0 0"/>
            <geometry>
                <sphere radius="0.0352"/>
            </geometry>
        </collision>

        <inertial>
            <origin rpy="0 1.5707 1.5707" xyz="0 0 0"/>
            <mass value="0.001"/>
            <inertia ixx="4.956160000000001e-07" ixy="0" ixz="0" iyy="4.956160000000001e-07" iyz="0" izz="4.956160000000001e-07"/>
        </inertial>
    </link>

    <gazebo reference="front_pitch_link">
        <kp>1000000000000000000000000000.0</kp>
        <kd>1000000000000000000000000000.0</kd>
        <mu1>0.5</mu1>
        <mu2>0.5</mu2>
        <material>Gazebo/Yellow</material>
    </gazebo>

    <!-- Caster Wheel Back -->
    <link name="back_yaw_link">
        <visual>
            <origin rpy="0 1.5707 1.5707" xyz="0 0 0"/>
            <geometry>
                <cylinder length="0.001" radius="0.0352"/>
            </geometry>
            <material name="blue"/>
        </visual>

        <collision>
            <origin rpy="0 1.5707 1.5707" xyz="0 0 0"/>
            <geometry>
                <cylinder length="0.001" radius="0.0352"/>
            </geometry>
        </collision>

        <inertial>
            <origin rpy="0 1.5707 1.5707" xyz="0 0 0"/>
            <mass value="0.001"/>
            <inertia ixx="3.0984333333333335e-07" ixy="0" ixz="0" iyy="3.0984333333333335e-07" iyz="0" izz="6.195200000000001e-07"/>
        </inertial>
    </link>

    <gazebo reference="back_yaw_link">
        <material>Gazebo/Blue</material>
    </gazebo>

    <link name="back_roll_link">

        <visual>
            <origin rpy="0 1.5707 1.5707" xyz="0 0 0"/>
            <geometry>
                <cylinder length="0.001" radius="0.0352"/>
            </geometry>
            <material name="red"/>
        </visual>

        <collision>
            <origin rpy="0 1.5707 1.5707" xyz="0 0 0"/>
            <geometry>
                <cylinder length="0.001" radius="0.0352"/>
            </geometry>
        </collision>

        <inertial>
            <origin rpy="0 1.5707 1.5707" xyz="0 0 0"/>
            <mass value="0.001"/>
            <inertia ixx="3.0984333333333335e-07" ixy="0" ixz="0" iyy="3.0984333333333335e-07" iyz="0" izz="6.195200000000001e-07"/>
        </inertial>

    </link>

    <gazebo reference="back_roll_link">
        <material>Gazebo/Red</material>
    </gazebo>

    <link name="back_pitch_link">
        <visual>
            <origin rpy="0 1.5707 1.5707" xyz="0 0 0"/>
            <geometry>
            <sphere radius="0.0352"/>
            </geometry>
            <material name="yellow"/>
        </visual>

        <collision>
            <origin rpy="0 1.5707 1.5707" xyz="0 0 0"/>
            <geometry>
                <sphere radius="0.0352"/>
            </geometry>
        </collision>

        <inertial>
            <origin rpy="0 1.5707 1.5707" xyz="0 0 0"/>
            <mass value="0.001"/>
            <inertia ixx="4.956160000000001e-07" ixy="0" ixz="0" iyy="4.956160000000001e-07" iyz="0" izz="4.956160000000001e-07"/>
        </inertial>

    </link>

    <gazebo reference="back_pitch_link">
        <kp>1000000000000000000000000000.0</kp>
        <kd>1000000000000000000000000000.0</kd>
        <mu1>0.5</mu1>
        <mu2>0.5</mu2>
        <material>Gazebo/Yellow</material>
    </gazebo>

    <xacro:macro name="laser">

        <!--xacro:laser include_laser="${include_laser}"/-->

            <link name="laser_scan_link">
            
                <visual>
                    <origin rpy="0 0 0" xyz="0 0 0"/>
                    <geometry>
                        <box size="0.02 0.02 0.02"/>
                    </geometry>
                </visual>

                <collision>
                    <origin rpy="0 0 0" xyz="0 0 0.0204"/>
                    <geometry>
                        <box size="0.02 0.02 0.02"/>
                    </geometry>
                </collision>

                <inertial>
                    <mass value="0.01"/>
                    <origin rpy="0 0 0" xyz="0 0 0.0204"/>
                    <inertia ixx="6.066578520833334e-06" ixy="0" ixz="0" iyy="6.072950163333333e-06" iyz="0" izz="9.365128684166666e-06"/>
                </inertial>

            </link>

            <link name="laser_scan_frame">
            </link>

            <link name="laser_scan_model_link">

                <visual>
                    <origin rpy="0 0 0" xyz="0 0 0"/>
                    <geometry>
                        <mesh filename="package://barista_robot_description/meshes/sick_s300.dae" scale="1.0 1.0 1.0"/>
                    </geometry>
                </visual>

                <collision>
                    <origin rpy="0 0 0" xyz="0 0 0.0204"/>
                    <geometry>
                        <cylinder length="0.0408" radius="0.037493"/>
                    </geometry>
                </collision>

                <inertial>
                    <mass value="0.01"/>
                    <origin rpy="0 0 0" xyz="0 0 0.0204"/>
                    <inertia ixx="6.066578520833334e-06" ixy="0" ixz="0" iyy="6.072950163333333e-06" iyz="0" izz="9.365128684166666e-06"/>
                </inertial>

            </link>

            <!-- Laser Position Control-->
            <joint name="laser_scan_link_joint" type="prismatic">
                <!--origin rpy="0 0 0" xyz="0.0 0.0 0.155"/-->
                <origin rpy="0 0 0" xyz="0.0 0.0 0.3"/>
                <parent link="base_link"/>
                <child link="laser_scan_link"/>
                <axis xyz="0 0 1"/>
                <limit lower="-0.1" upper="0.0" effort="20.0" velocity="2.0"/>
                <dynamics damping="0.1" friction="1.0"/>
            </joint>

            <!-- -->>
            <joint name="laser_scan_frame_joint" type="fixed">
                <origin rpy="0 0 0" xyz="0 0 0.0"/>
                <parent link="laser_scan_link"/>
                <child link="laser_scan_frame"/>
                <axis xyz="0 0 0"/>
            </joint>

            <!-- Visual Laser Model to be rotated -->
            <joint name="laser_scan_model_link_joint" type="continuous">
                <!--origin rpy="0 0 -1.57" xyz="0.0 0.0 0.0"/-->
                <origin rpy="0 0 -1.57" xyz="0.0 0.0 -0.145"/>
                <parent link="laser_scan_link"/>
                <child link="laser_scan_model_link"/>
                <axis xyz="0 0 1"/>
                <limit effort="10.0" velocity="2.0"/>
                <dynamics friction="0.01"/>
            </joint>

            <gazebo reference="laser_scan_frame">
                <sensor name="sensor_ray" type="ray">
                    <pose>0 0 0 0 0 0</pose>
                    <ray>
                    <scan>
                        <horizontal>
                        <samples>200</samples>
                        <resolution>1.0</resolution>
                        <min_angle>-3.14</min_angle>
                        <max_angle>3.14</max_angle>
                        </horizontal>
                    </scan>
                    <range>
                        <min>0.1</min>
                        <max>5.0</max>
                    </range>
                    </ray>
                    <always_on>true</always_on>
                    <visualize>true</visualize>
                    <update_rate>100.0</update_rate>
                    <plugin name="laser" filename="libgazebo_ros_ray_sensor.so">
                    <ros>
                        <remapping>~/out:=scan</remapping>
                    </ros>
                    <output_type>sensor_msgs/LaserScan</output_type>
                    </plugin>
                </sensor>
            </gazebo>


            <!-- Position Config -->
            <ros2_control name="GazeboSystem" type="system">

                <hardware>
                <plugin>gazebo_ros2_control/GazeboSystem</plugin>
                </hardware>

                <joint name="laser_scan_link_joint">
                    <command_interface name="position">
                        <param name="min">-0.05</param>
                        <param name="max">0.0</param>
                    </command_interface>
                    <state_interface name="position"/>
                    <state_interface name="velocity"/>
                    <state_interface name="effort"/>
                </joint>

                <joint name="laser_scan_model_link_joint">
                    <command_interface name="velocity">
                        <param name="min">0.0</param>
                        <param name="max">2.0</param>
                    </command_interface>
                    <state_interface name="position"/>
                    <state_interface name="velocity"/>
                    <state_interface name="effort"/>
                </joint>

            </ros2_control>

    </xacro:macro>

    <xacro:if value="${include_laser}">
        <xacro:laser/>
    </xacro:if>
    

    <!-- ******************************************** Joints ******************************************** -->

    <joint name="base_link_to_standoff_rods_1_joint" type="fixed">
        <origin rpy="0 0 0" xyz="0.10 0.05 0.1875" />
        <parent link="base_link" />
        <child link="standoff_rods_1" />
    </joint>

    <joint name="base_link_to_standoff_rods_2_joint" type="fixed">
        <origin rpy="0 0 0" xyz="-0.10 0.05 0.1875" />
        <parent link="base_link" />
        <child link="standoff_rods_2" />
    </joint>

    <joint name="base_link_to_standoff_rods_3_joint" type="fixed">
        <origin rpy="0 0 0" xyz="0.10 -0.05 0.1875" />
        <parent link="base_link" />
        <child link="standoff_rods_3" />
    </joint>

    <joint name="base_link_to_standoff_rods_4_joint" type="fixed">
        <origin rpy="0 0 0" xyz="-0.10 -0.05 0.1875" />
        <parent link="base_link" />
        <child link="standoff_rods_4" />
    </joint>

    <joint name="base_link_to_cup_holder_tray_joint" type="fixed">
        <origin rpy="0 0 0" xyz="0 0 0.3425" />
        <parent link="base_link" />
        <child link="cup_holder_tray" />
    </joint>

    <joint name="base_link_to_left_wheel_joint" type="continuous">  
        <origin rpy="0 0 0" xyz="0.11 0 -0.0775" />
        <parent link="base_link" />
        <child link="left_wheel" />
        <axis rpy="0 0 0" xyz="1 0 0"/>
        <limit effort="10000" velocity="1000"/>
        <joint_properties damping="1.0" friction="1.0"/>
    </joint>

    <joint name="base_link_to_right_wheel_joint" type="continuous">  
        <origin rpy="0 0 0" xyz="-0.11 0 -0.0775" />
        <parent link="base_link" />
        <child link="right_wheel" />
        <axis rpy="0 0 0" xyz="1 0 0"/>
        <limit effort="10000" velocity="1000"/>
        <joint_properties damping="1.0" friction="1.0"/>
    </joint>

    <joint name="front_yaw_joint" type="continuous">
        <origin rpy="0 0 0" xyz="0 0.1 -0.0775"/>
        <parent link="base_link" />
        <child link="front_yaw_link" />
        <axis xyz="0 0 1" />
        <limit effort="1000.0" velocity="100.0" />
        <dynamics damping="0.0" friction="0.1"/>
    </joint>

    <joint name="front_roll_joint" type="continuous">
        <origin rpy="0 0 0" xyz="0 0 0" />
        <parent link="front_yaw_link" />
        <child link="front_roll_link" />
        <axis xyz="1 0 0" />
        <limit effort="1000.0" velocity="100.0" />
        <dynamics damping="0.0" friction="0.1"/>
    </joint>

    <joint name="front_pitch_joint" type="continuous">
        <origin rpy="0 0 0" xyz="0 0 0" />
        <parent link="front_roll_link" />
        <child link="front_pitch_link" />
        <axis xyz="0 1 0" />
        <limit effort="1000.0" velocity="100.0" />
        <dynamics damping="0.0" friction="0.1"/>
    </joint>

    <joint name="back_yaw_joint" type="continuous">
        <origin rpy="0 0 0" xyz="0 -0.1 -0.0775"/>
        <parent link="base_link" />
        <child link="back_yaw_link" />
        <axis xyz="0 0 1" />
        <limit effort="1000.0" velocity="100.0" />
        <dynamics damping="0.0" friction="0.1"/>
    </joint>

    <joint name="back_roll_joint" type="continuous">
        <origin rpy="0 0 0" xyz="0 0 0" />
        <parent link="back_yaw_link" />
        <child link="back_roll_link" />
        <axis xyz="1 0 0" />
        <limit effort="1000.0" velocity="100.0" />
        <dynamics damping="0.0" friction="0.1"/>
    </joint>

    <joint name="back_pitch_joint" type="continuous">
        <origin rpy="0 0 0" xyz="0 0 0" />
        <parent link="back_roll_link" />
        <child link="back_pitch_link" />
        <axis xyz="0 1 0" />
        <limit effort="1000.0" velocity="100.0" />
        <dynamics damping="0.0" friction="0.1"/>
    </joint>



    <!-- ******************************************** PLUGINS ******************************************** -->


    <!-- JOINT PUBLISHER -->
    <gazebo>
        <plugin name="box_bot_joint_state" filename="libgazebo_ros_joint_state_publisher.so">
            <ros>
                <remapping>~/out:=joint_states</remapping>
            </ros>
            <update_rate>30</update_rate>

            <joint_name>base_link_to_left_wheel_joint</joint_name>
            <joint_name>base_link_to_right_wheel_joint</joint_name>
            <joint_name>back_yaw_joint</joint_name>
            <joint_name>back_roll_joint</joint_name>
            <joint_name>back_pitch_joint</joint_name>
            <joint_name>front_yaw_joint</joint_name>
            <joint_name>front_roll_joint</joint_name>
            <joint_name>front_pitch_joint</joint_name>
            <joint_name>laser_scan_link_joint</joint_name>
            <joint_name>laser_scan_frame_joint</joint_name>
            <joint_name>laser_scan_model_link_joint</joint_name>

        </plugin>
    </gazebo>

    <!-- Differential drive -->
    <gazebo>
        <plugin filename="libgazebo_ros_diff_drive.so" name="differential_drive_controller">

            <!-- wheels -->
            <left_joint>base_link_to_left_wheel_joint</left_joint>
            <right_joint>base_link_to_right_wheel_joint</right_joint>
            
            <!-- kinematics -->
            <wheel_separation>0.22</wheel_separation>
            <wheel_diameter>0.0704</wheel_diameter>

            <!-- limits -->
            <max_wheel_torque>1.0</max_wheel_torque>
            <max_wheel_acceleration>2.0</max_wheel_acceleration>

            <!-- output -->
            <publish_odom>true</publish_odom>
            <publish_odom_tf>true</publish_odom_tf>

            <odometry_frame>odom</odometry_frame>
            <robot_base_frame>base_link</robot_base_frame>

        </plugin>
    </gazebo>





</robot>